[2024-06-04T23:24:31.073+0000] {taskinstance.py:1125} INFO - Dependencies all met for dep_context=non-requeueable deps ti=<TaskInstance: ETL_toll_data_03.unzip_data manual__2024-06-04T23:19:27.340173+00:00 [queued]>
[2024-06-04T23:24:31.090+0000] {taskinstance.py:1125} INFO - Dependencies all met for dep_context=requeueable deps ti=<TaskInstance: ETL_toll_data_03.unzip_data manual__2024-06-04T23:19:27.340173+00:00 [queued]>
[2024-06-04T23:24:31.090+0000] {taskinstance.py:1331} INFO - Starting attempt 2 of 2
[2024-06-04T23:24:31.114+0000] {taskinstance.py:1350} INFO - Executing <Task(_PythonDecoratedOperator): unzip_data> on 2024-06-04 23:19:27.340173+00:00
[2024-06-04T23:24:31.122+0000] {standard_task_runner.py:57} INFO - Started process 488 to run task
[2024-06-04T23:24:31.129+0000] {standard_task_runner.py:84} INFO - Running: ['***', 'tasks', 'run', 'ETL_toll_data_03', 'unzip_data', 'manual__2024-06-04T23:19:27.340173+00:00', '--job-id', '195', '--raw', '--subdir', 'DAGS_FOLDER/ETL_toll_data.py', '--cfg-path', '/tmp/tmpj1tv8ej2']
[2024-06-04T23:24:31.130+0000] {standard_task_runner.py:85} INFO - Job 195: Subtask unzip_data
[2024-06-04T23:24:31.208+0000] {task_command.py:410} INFO - Running <TaskInstance: ETL_toll_data_03.unzip_data manual__2024-06-04T23:19:27.340173+00:00 [running]> on host 505f5496b4af
[2024-06-04T23:24:31.334+0000] {taskinstance.py:1570} INFO - Exporting env vars: AIRFLOW_CTX_DAG_EMAIL='naveedcodes@gmail.com' AIRFLOW_CTX_DAG_OWNER='naveed' AIRFLOW_CTX_DAG_ID='ETL_toll_data_03' AIRFLOW_CTX_TASK_ID='unzip_data' AIRFLOW_CTX_EXECUTION_DATE='2024-06-04T23:19:27.340173+00:00' AIRFLOW_CTX_TRY_NUMBER='2' AIRFLOW_CTX_DAG_RUN_ID='manual__2024-06-04T23:19:27.340173+00:00'
[2024-06-04T23:24:31.338+0000] {taskinstance.py:1847} ERROR - Task failed with exception
Traceback (most recent call last):
  File "/home/airflow/.local/lib/python3.7/site-packages/airflow/decorators/base.py", line 220, in execute
    return_value = super().execute(context)
  File "/home/airflow/.local/lib/python3.7/site-packages/airflow/operators/python.py", line 181, in execute
    return_value = self.execute_callable()
  File "/home/airflow/.local/lib/python3.7/site-packages/airflow/operators/python.py", line 198, in execute_callable
    return self.python_callable(*self.op_args, **self.op_kwargs)
  File "/opt/airflow/dags/ETL_toll_data.py", line 29, in unzip_data
    with tarfile.open(source) as file:
  File "/usr/local/lib/python3.7/tarfile.py", line 1575, in open
    return func(name, "r", fileobj, **kwargs)
  File "/usr/local/lib/python3.7/tarfile.py", line 1639, in gzopen
    fileobj = GzipFile(name, mode + "b", compresslevel, fileobj)
  File "/usr/local/lib/python3.7/gzip.py", line 168, in __init__
    fileobj = self.myfileobj = builtins.open(filename, mode or 'rb')
FileNotFoundError: [Errno 2] No such file or directory: 'data_source/tolldata.tgz'
[2024-06-04T23:24:31.351+0000] {taskinstance.py:1373} INFO - Marking task as FAILED. dag_id=ETL_toll_data_03, task_id=unzip_data, execution_date=20240604T231927, start_date=20240604T232431, end_date=20240604T232431
[2024-06-04T23:24:31.372+0000] {warnings.py:110} WARNING - /home/***/.local/lib/python3.7/site-packages/***/utils/email.py:152: RemovedInAirflow3Warning: Fetching SMTP credentials from configuration variables will be deprecated in a future release. Please set credentials using a connection instead.
  send_mime_email(e_from=mail_from, e_to=recipients, mime_msg=msg, conn_id=conn_id, dryrun=dryrun)

[2024-06-04T23:24:31.372+0000] {configuration.py:675} WARNING - section/key [smtp/smtp_user] not found in config
[2024-06-04T23:24:31.374+0000] {email.py:268} INFO - Email alerting: attempt 1
[2024-06-04T23:24:31.385+0000] {configuration.py:675} WARNING - section/key [smtp/smtp_user] not found in config
[2024-06-04T23:24:31.385+0000] {email.py:268} INFO - Email alerting: attempt 1
[2024-06-04T23:24:31.387+0000] {taskinstance.py:1912} ERROR - Failed to send email to: naveedcodes@gmail.com
Traceback (most recent call last):
  File "/home/airflow/.local/lib/python3.7/site-packages/airflow/models/taskinstance.py", line 1430, in _run_raw_task
    self._execute_task_with_callbacks(context, test_mode)
  File "/home/airflow/.local/lib/python3.7/site-packages/airflow/models/taskinstance.py", line 1581, in _execute_task_with_callbacks
    result = self._execute_task(context, task_orig)
  File "/home/airflow/.local/lib/python3.7/site-packages/airflow/models/taskinstance.py", line 1651, in _execute_task
    result = execute_callable(context=context)
  File "/home/airflow/.local/lib/python3.7/site-packages/airflow/decorators/base.py", line 220, in execute
    return_value = super().execute(context)
  File "/home/airflow/.local/lib/python3.7/site-packages/airflow/operators/python.py", line 181, in execute
    return_value = self.execute_callable()
  File "/home/airflow/.local/lib/python3.7/site-packages/airflow/operators/python.py", line 198, in execute_callable
    return self.python_callable(*self.op_args, **self.op_kwargs)
  File "/opt/airflow/dags/ETL_toll_data.py", line 29, in unzip_data
    with tarfile.open(source) as file:
  File "/usr/local/lib/python3.7/tarfile.py", line 1575, in open
    return func(name, "r", fileobj, **kwargs)
  File "/usr/local/lib/python3.7/tarfile.py", line 1639, in gzopen
    fileobj = GzipFile(name, mode + "b", compresslevel, fileobj)
  File "/usr/local/lib/python3.7/gzip.py", line 168, in __init__
    fileobj = self.myfileobj = builtins.open(filename, mode or 'rb')
FileNotFoundError: [Errno 2] No such file or directory: 'data_source/tolldata.tgz'

During handling of the above exception, another exception occurred:

Traceback (most recent call last):
  File "/home/airflow/.local/lib/python3.7/site-packages/airflow/models/taskinstance.py", line 2318, in email_alert
    send_email(task.email, subject, html_content)
  File "/home/airflow/.local/lib/python3.7/site-packages/airflow/utils/email.py", line 91, in send_email
    **kwargs,
  File "/home/airflow/.local/lib/python3.7/site-packages/airflow/utils/email.py", line 152, in send_email_smtp
    send_mime_email(e_from=mail_from, e_to=recipients, mime_msg=msg, conn_id=conn_id, dryrun=dryrun)
  File "/home/airflow/.local/lib/python3.7/site-packages/airflow/utils/email.py", line 270, in send_mime_email
    smtp_conn = _get_smtp_connection(smtp_host, smtp_port, smtp_timeout, smtp_ssl)
  File "/home/airflow/.local/lib/python3.7/site-packages/airflow/utils/email.py", line 317, in _get_smtp_connection
    else smtplib.SMTP(host=host, port=port, timeout=timeout)
  File "/usr/local/lib/python3.7/smtplib.py", line 251, in __init__
    (code, msg) = self.connect(host, port)
  File "/usr/local/lib/python3.7/smtplib.py", line 336, in connect
    self.sock = self._get_socket(host, port, self.timeout)
  File "/usr/local/lib/python3.7/smtplib.py", line 307, in _get_socket
    self.source_address)
  File "/usr/local/lib/python3.7/socket.py", line 728, in create_connection
    raise err
  File "/usr/local/lib/python3.7/socket.py", line 716, in create_connection
    sock.connect(sa)
ConnectionRefusedError: [Errno 111] Connection refused

During handling of the above exception, another exception occurred:

Traceback (most recent call last):
  File "/home/airflow/.local/lib/python3.7/site-packages/airflow/models/taskinstance.py", line 1910, in handle_failure
    self.email_alert(error, task)
  File "/home/airflow/.local/lib/python3.7/site-packages/airflow/models/taskinstance.py", line 2320, in email_alert
    send_email(task.email, subject, html_content_err)
  File "/home/airflow/.local/lib/python3.7/site-packages/airflow/utils/email.py", line 91, in send_email
    **kwargs,
  File "/home/airflow/.local/lib/python3.7/site-packages/airflow/utils/email.py", line 152, in send_email_smtp
    send_mime_email(e_from=mail_from, e_to=recipients, mime_msg=msg, conn_id=conn_id, dryrun=dryrun)
  File "/home/airflow/.local/lib/python3.7/site-packages/airflow/utils/email.py", line 270, in send_mime_email
    smtp_conn = _get_smtp_connection(smtp_host, smtp_port, smtp_timeout, smtp_ssl)
  File "/home/airflow/.local/lib/python3.7/site-packages/airflow/utils/email.py", line 317, in _get_smtp_connection
    else smtplib.SMTP(host=host, port=port, timeout=timeout)
  File "/usr/local/lib/python3.7/smtplib.py", line 251, in __init__
    (code, msg) = self.connect(host, port)
  File "/usr/local/lib/python3.7/smtplib.py", line 336, in connect
    self.sock = self._get_socket(host, port, self.timeout)
  File "/usr/local/lib/python3.7/smtplib.py", line 307, in _get_socket
    self.source_address)
  File "/usr/local/lib/python3.7/socket.py", line 728, in create_connection
    raise err
  File "/usr/local/lib/python3.7/socket.py", line 716, in create_connection
    sock.connect(sa)
ConnectionRefusedError: [Errno 111] Connection refused
[2024-06-04T23:24:31.410+0000] {standard_task_runner.py:109} ERROR - Failed to execute job 195 for task unzip_data ([Errno 2] No such file or directory: 'data_source/tolldata.tgz'; 488)
[2024-06-04T23:24:31.431+0000] {local_task_job_runner.py:232} INFO - Task exited with return code 1
[2024-06-04T23:24:31.454+0000] {taskinstance.py:2674} INFO - 0 downstream tasks scheduled from follow-on schedule check
